Workbook
Name d_Age: Data!$B$2:$B$5000
Name d_Att: Data!$H$2:$H$5000
Name d_Dept: Data!$C$2:$C$5000
Name d_ID: Data!$A$2:$A$5000
Name d_Prom: Data!$G$2:$G$5000
Name d_Sal: Data!$D$2:$D$5000
Name d_Sat: Data!$F$2:$F$5000
Name d_Ten: Data!$E$2:$E$5000
Name DeptList: OFFSET(Settings!$B$6,0,0,1+COUNTA(Settings!$B$7:$B$14),1)
Name fDept: Calc!$C$3
Name FiltersOn: Calc!$C$8
Name fPromHi: Calc!$C$7
Name fPromLo: Calc!$C$6
Name fSatHi: Calc!$C$5
Name fSatLo: Calc!$C$4
Name PromList: Settings!$F$6:$F$8
Name SatLevels: Settings!$D$7:$D$10
Name SatList: Settings!$D$6:$D$10
Name TargetAttr: Settings!$C$18

Sheet Dashboard
B2: HR WORKFORCE ANALYTICS | R2: =IF(Settings!$C$28=0,"● LIVE | "&TEXT(Settings!$C$22,"#,##0")&" records | data checks passed","▲ "&Settings!$C$28&" DATA ISSUE(S) — SEE SETTINGS") -> ● LIVE | 800 records | data checks passed
B3: Attrition · Compensation · Career growth | Fully live: edit the Data sheet or use the filters below
B5: DEPARTMENT | G5: JOB SATISFACTION | L5: PROMOTED (LAST 5 YRS) | Q5: ▼ Pick from the dropdowns — every KPI, chart and insight updates instantly. Choose “All” to reset.
B6: All | G6: All | L6: All
B9: HEADCOUNT | F9: EMPLOYEES LEFT | J9: ATTRITION RATE | N9: AVERAGE SALARY | R9: JOB SATISFACTION | V9: PROMOTION RATE
B10: =Calc!D12 -> 800 | F10: =Calc!D13 -> 146 | J10: =Calc!D14 -> 0.1825 | N10: =Calc!D15 -> 75061.798 | R10: =Calc!D16 -> 2.49625 | V10: =Calc!D17 -> 0.32625
B12: =IF(Calc!$C$8=1,TEXT(IFERROR(Calc!D12/Calc!C12,0),"0.0%")&" of total workforce","Total workforce") -> Total workforce | F12: ="Retained: "&TEXT(Calc!D12-Calc!D13,"#,##0") -> Retained: 654 | J12: =IF(Calc!$C$8=1,IF(Calc!D14>=Calc!C14,"▲ ","▼ ")&TEXT(ABS(Calc!D14-Calc!C14)*100,"0.0")&" pp vs company",IF(Calc!D14>TargetAttr,"▲ Above ","▼ Within ")&"target of "&TEXT(TargetAttr,"0%")) -> ▲ Above target of 15% | N12: =IF(Calc!$C$8=1,IF(Calc!D15>=Calc!C15,"▲ ","▼ ")&TEXT(ABS(IFERROR(Calc!D15/Calc!C15-1,0)),"0.0%")&" vs company","Leavers: "&TEXT(Calc!E85,"$#,##0")) -> Leavers: $75,981 | R12: =IF(Calc!$C$8=1,IF(Calc!D16>=Calc!C16,"▲ ","▼ ")&TEXT(ABS(Calc!D16-Calc!C16),"0.00")&" vs company","Scale "&MIN(SatLevels)&" to "&MAX(SatLevels)) -> Scale 1 to 4 | V12: ="Promoted in last 5 yrs: "&TEXT(ROUND(Calc!D17*Calc!D12,0),"#,##0") -> Promoted in last 5 yrs: 261
B14: KEY INSIGHTS · generated automatically from the current selection
B15: ="◆ "&Calc!B108 -> ◆ Attrition is 18.3% (146 of 800 employees), above the 15% target.
B16: ="◆ "&Calc!B109 -> ◆ Highest-attrition department: Finance (22.9%); lowest: IT (13.2%).
B17: ="◆ "&Calc!B110 -> ◆ Employees rated 1 for job satisfaction leave at 19.4% vs 16.6% for those rated 4 — a modest gap, not a strong driver of attrition.
B18: ="◆ "&Calc!B111 -> ◆ Leavers earn on average $75,981 vs $74,857 for stayers (1.5% higher) — pay alone does not explain attrition.
B19: ="◆ "&Calc!B112 -> ◆ Employees promoted in the last 5 years leave at 16.1% vs 19.3% for those not promoted — career progression supports retention.
B21: 1 · ATTRITION ANALYSIS
B23: Attrition rate by department | J23: Employees who left, by job satisfaction | R23: Attrition rate by tenure
B24: Ranked high to low · department filter ignored | J24: Headcount that left at each rating | R24: Share of each tenure band that left
B39: Attrition rate by age band | J39: Workforce retention split | R39: Attrition heatmap
B40: Share of each age band that left | J40: Stayed vs left (current selection) | R40: Department × job satisfaction · darker red = higher attrition
R41: Department | U41: ="Rating "&Calc!C96 -> Rating 1 | V41: ="Rating "&Calc!D96 -> Rating 2 | W41: ="Rating "&Calc!E96 -> Rating 3 | X41: ="Rating "&Calc!F96 -> Rating 4 | Y41: All levels
R42: =Calc!B97 -> Finance | U42: =Calc!C97 -> 0.29166667 | V42: =Calc!D97 -> 0.32258065 | W42: =Calc!E97 -> 0.1627907 | X42: =Calc!F97 -> 0.16666667 | Y42: =Calc!G97 -> 0.22941176
R43: =Calc!B98 -> HR | U43: =Calc!C98 -> 0.19047619 | V43: =Calc!D98 -> 0.23255814 | W43: =Calc!E98 -> 0.175 | X43: =Calc!F98 -> 0.12244898 | Y43: =Calc!G98 -> 0.17816092
R44: =Calc!B99 -> IT | U44: =Calc!C99 -> 0.10869565 | V44: =Calc!D99 -> 0 | W44: =Calc!E99 -> 0.29411765 | X44: =Calc!F99 -> 0.13636364 | Y44: =Calc!G99 -> 0.13207547
R45: =Calc!B100 -> Operations | U45: =Calc!C100 -> 0.19047619 | V45: =Calc!D100 -> 0.14705882 | W45: =Calc!E100 -> 0.14705882 | X45: =Calc!F100 -> 0.15625 | Y45: =Calc!G100 -> 0.16197183
R46: =Calc!B101 -> Sales | U46: =Calc!C101 -> 0.18421053 | V46: =Calc!D101 -> 0.15384615 | W46: =Calc!E101 -> 0.225 | X46: =Calc!F101 -> 0.26315789 | Y46: =Calc!G101 -> 0.20645161
R47: =Calc!B102 | U47: =Calc!C102 | V47: =Calc!D102 | W47: =Calc!E102 | X47: =Calc!F102 | Y47: =Calc!G102
R48: =Calc!B103 | U48: =Calc!C103 | V48: =Calc!D103 | W48: =Calc!E103 | X48: =Calc!F103 | Y48: =Calc!G103
R49: =Calc!B104 | U49: =Calc!C104 | V49: =Calc!D104 | W49: =Calc!E104 | X49: =Calc!F104 | Y49: =Calc!G104
R51: Tip: use the Promoted filter to see whether career progression changes the pattern.
B55: 2 · COMPENSATION & ATTRITION
B57: Average salary: stayed vs left | J57: Average salary by department | R57: Attrition rate by salary band
B58: Is pay different for people who leave? | J58: Ranked high to low · department filter ignored | R58: Share of each pay band that left
B73: Average salary by job satisfaction | J73: Average salary by tenure | R73: Average salary by age band
B74: Do happier employees earn more? | J74: Pay progression with time at the company | R74: Pay across age groups
B89: 3 · PROMOTION & CAREER GROWTH
B91: Attrition: promoted vs not promoted | J91: Promotion rate by department | R91: Promotion rate by tenure
B92: Promotion in the last 5 years (promotion filter ignored) | J92: Ranked high to low · department filter ignored | R92: Are long-serving staff being promoted?
B107: DEPARTMENT SCORECARD · highlights the department selected above
B109: Department | E109: Headcount | H109: Left | K109: Attrition % | N109: Avg salary | Q109: Avg satisfaction | T109: Promotion % | W109: Avg tenure (yrs)
B110: =Calc!B25 -> Finance | E110: =Calc!C25 -> 170 | H110: =Calc!D25 -> 39 | K110: =Calc!E25 -> 0.22941176 | N110: =Calc!F25 -> 74193.429 | Q110: =Calc!G25 -> 2.5352941 | T110: =Calc!H25 -> 0.34705882 | W110: =Calc!I25 -> 8.6941176
B111: =Calc!B26 -> HR | E111: =Calc!C26 -> 174 | H111: =Calc!D26 -> 31 | K111: =Calc!E26 -> 0.17816092 | N111: =Calc!F26 -> 73784.241 | Q111: =Calc!G26 -> 2.5517241 | T111: =Calc!H26 -> 0.3045977 | W111: =Calc!I26 -> 9.4770115
...

Sheet Data
A1: EmployeeID | B1: Age | C1: Department | D1: Salary | E1: Years At Company | F1: Job Satisfaction | G1: Promotion Last 5Years | H1: Attrition
A2: EMP1000 | B2: 38 | C2: IT | D2: 46639 | E2: 5 | F2: 1 | G2: 0 | H2: No
A3: EMP1001 | B3: 55 | C3: HR | D3: 115030 | E3: 9 | F3: 2 | G3: 0 | H3: Yes
A4: EMP1002 | B4: 37 | C4: Operations | D4: 94566 | E4: 1 | F4: 1 | G4: 0 | H4: No
A5: EMP1003 | B5: 56 | C5: IT | D5: 72011 | E5: 6 | F5: 2 | G5: 1 | H5: No
A6: EMP1004 | B6: 48 | C6: HR | D6: 48640 | E6: 16 | F6: 3 | G6: 0 | H6: Yes
A7: EMP1005 | B7: 35 | C7: HR | D7: 65402 | E7: 2 | F7: 2 | G7: 0 | H7: No
A8: EMP1006 | B8: 39 | C8: Operations | D8: 95088 | E8: 19 | F8: 4 | G8: 1 | H8: No
A9: EMP1007 | B9: 42 | C9: Operations | D9: 90240 | E9: 11 | F9: 2 | G9: 0 | H9: No
A10: EMP1008 | B10: 26 | C10: Operations | D10: 31891 | E10: 1 | F10: 3 | G10: 1 | H10: No
A11: EMP1009 | B11: 27 | C11: Sales | D11: 58259 | E11: 6 | F11: 2 | G11: 0 | H11: No
A12: EMP1010 | B12: 29 | C12: HR | D12: 93021 | E12: 16 | F12: 2 | G12: 0 | H12: No
A13: EMP1011 | B13: 40 | C13: Operations | D13: 58987 | E13: 18 | F13: 3 | G13: 0 | H13: No
... A801: EMP1799 | B801: 29 | C801: HR | D801: 73382 | E801: 12 | F801: 3 | G801: 0 | H801: No

Sheet Settings
B2: Settings & Data Quality
A3: Blue cells are inputs you can edit. Everything on the Dashboard recalculates from these and from the Data sheet.
B5: Departments | D5: Satisfaction | F5: Promotion filter | H5: Tenure band | I5: Min yrs | J5: Max yrs | L5: Age band | M5: Min | N5: Max | P5: Salary band | Q5: Min $ | R5: Max $
B6: All | D6: All | F6: All | H6: =IF(J6>=999,I6&"+ yrs",I6&"–"&J6&" yrs") -> 0–2 yrs | I6: 0 | J6: 2 | L6: =IF(M6<=0,"Under "&(N6+1),IF(N6>=999,M6&"+",M6&"–"&N6)) -> Under 30 | M6: 0 | N6: 29 | P6: =IF(Q6<=0,"Under $"&TEXT((R6+1)/1000,"0")&"k",IF(R6>=999999,"$"&TEXT(Q6/1000,"0")&"k+","$"&TEXT(Q6/1000,"0")&"k–$"&TEXT((R6+1)/1000,"0")&"k")) -> Under $50k | Q6: 0 | R6: 49999
B7: Finance | D7: 1 | F7: Promoted | H7: =IF(J7>=999,I7&"+ yrs",I7&"–"&J7&" yrs") -> 3–5 yrs | I7: 3 | J7: 5 | L7: =IF(M7<=0,"Under "&(N7+1),IF(N7>=999,M7&"+",M7&"–"&N7)) -> 30–39 | M7: 30 | N7: 39 | P7: =IF(Q7<=0,"Under $"&TEXT((R7+1)/1000,"0")&"k",IF(R7>=999999,"$"&TEXT(Q7/1000,"0")&"k+","$"&TEXT(Q7/1000,"0")&"k–$"&TEXT((R7+1)/1000,"0")&"k")) -> $50k–$70k | Q7: 50000 | R7: 69999
B8: HR | D8: 2 | F8: Not promoted | H8: =IF(J8>=999,I8&"+ yrs",I8&"–"&J8&" yrs") -> 6–10 yrs | I8: 6 | J8: 10 | L8: =IF(M8<=0,"Under "&(N8+1),IF(N8>=999,M8&"+",M8&"–"&N8)) -> 40–49 | M8: 40 | N8: 49 | P8: =IF(Q8<=0,"Under $"&TEXT((R8+1)/1000,"0")&"k",IF(R8>=999999,"$"&TEXT(Q8/1000,"0")&"k+","$"&TEXT(Q8/1000,"0")&"k–$"&TEXT((R8+1)/1000,"0")&"k")) -> $70k–$90k | Q8: 70000 | R8: 89999
B9: IT | D9: 3 | H9: =IF(J9>=999,I9&"+ yrs",I9&"–"&J9&" yrs") -> 11–15 yrs | I9: 11 | J9: 15 | L9: =IF(M9<=0,"Under "&(N9+1),IF(N9>=999,M9&"+",M9&"–"&N9)) -> 50+ | M9: 50 | N9: 999 | P9: =IF(Q9<=0,"Under $"&TEXT((R9+1)/1000,"0")&"k",IF(R9>=999999,"$"&TEXT(Q9/1000,"0")&"k+","$"&TEXT(Q9/1000,"0")&"k–$"&TEXT((R9+1)/1000,"0")&"k")) -> $90k–$110k | Q9: 90000 | R9: 109999
B10: Operations | D10: 4 | H10: =IF(J10>=999,I10&"+ yrs",I10&"–"&J10&" yrs") -> 16+ yrs | I10: 16 | J10: 999 | P10: =IF(Q10<=0,"Under $"&TEXT((R10+1)/1000,"0")&"k",IF(R10>=999999,"$"&TEXT(Q10/1000,"0")&"k+","$"&TEXT(Q10/1000,"0")&"k–$"&TEXT((R10+1)/1000,"0")&"k")) -> $110k+ | Q10: 110000 | R10: 999999
B11: Sales
B16: Targets & assumptions
B18: Attrition target | C18: 0.15 | D18: ASSUMPTION: 15% is a placeholder benchmark. Replace with your organisation's approved target.
B19: Tip: bands use inclusive limits; 999 / 999,999 means “and above”. Add a new department in the next empty cell of the Departments list.
B21: Data quality checks
B22: Records in Data sheet | C22: =COUNTA(d_ID) -> 800
B23: Departments not in the Settings list | C23: =C22-SUM(Calc!J25:J32) -> 0 | D23: =IF(C23=0,"✔ OK","✖ Review") -> ✔ OK
B24: Attrition values other than Yes / No | C24: =C22-COUNTIFS(d_ID,"<>",d_Att,"Yes")-COUNTIFS(d_ID,"<>",d_Att,"No") -> 0 | D24: =IF(C24=0,"✔ OK","✖ Review") -> ✔ OK
B25: Job satisfaction outside the scale | C25: =C22-COUNTIFS(d_ID,"<>",d_Sat,">="&MIN(SatLevels),d_Sat,"<="&MAX(SatLevels)) -> 0 | D25: =IF(C25=0,"✔ OK","✖ Review") -> ✔ OK
B26: Promotion flag not 0 / 1 | C26: =C22-COUNTIFS(d_ID,"<>",d_Prom,">=0",d_Prom,"<=1") -> 0 | D26: =IF(C26=0,"✔ OK","✖ Review") -> ✔ OK
B27: Missing values in required columns | C27: =C22*7-(COUNT(d_Age)+COUNTA(d_Dept)+COUNT(d_Sal)+COUNT(d_Ten)+COUNT(d_Sat)+COUNT(d_Prom)+COUNTA(d_Att)) -> 0 | D27: =IF(C27=0,"✔ OK","✖ Review") -> ✔ OK
B28: Total issues | C28: =SUM(C23:C27) -> 0 | D28: =IF(C28=0,"✔ OK","✖ Review") -> ✔ OK
B29: Duplicate Employee IDs are highlighted red on the Data sheet (column A).

Sheet Calc
B1: Calculation engine — all dashboard numbers are computed here from the Data sheet. No inputs on this sheet.
B2: Active filters (read from Dashboard)
B3: Department criterion | C3: =IF(Dashboard!$B$6="All","*",Dashboard!$B$6) -> *
B4: Satisfaction min | C4: =IF(Dashboard!$G$6="All",0,VALUE(Dashboard!$G$6)) -> 0
B5: Satisfaction max | C5: =IF(Dashboard!$G$6="All",9999,VALUE(Dashboard!$G$6)) -> 9999
B6: Promotion min | C6: =IF(Dashboard!$L$6="Promoted",1,0) -> 0
B7: Promotion max | C7: =IF(Dashboard!$L$6="Not promoted",0,9999) -> 9999
B8: Any filter on? (1/0) | C8: =IF(AND(Dashboard!$B$6="All",Dashboard!$G$6="All",Dashboard!$L$6="All"),0,1) -> 0
B11: Metric | C11: Company (no filters) | D11: Selection (filters)
B12: Headcount | C12: =COUNTIFS(d_ID,"<>") -> 800 | D12: =COUNTIFS(d_ID,"<>",d_Dept,fDept,d_Sat,">="&fSatLo,d_Sat,"<="&fSatHi,d_Prom,">="&fPromLo,d_Prom,"<="&fPromHi) -> 800
B13: Employees left | C13: =COUNTIFS(d_ID,"<>",d_Att,"Yes") -> 146 | D13: =COUNTIFS(d_ID,"<>",d_Dept,fDept,d_Sat,">="&fSatLo,d_Sat,"<="&fSatHi,d_Prom,">="&fPromLo,d_Prom,"<="&fPromHi,d_Att,"Yes") -> 146
B14: Attrition rate | C14: =IFERROR(C13/C12,0) -> 0.1825 | D14: =IFERROR(D13/D12,0) -> 0.1825
B15: Average salary | C15: =IFERROR(AVERAGEIFS(d_Sal,d_ID,"<>"),0) -> 75061.798 | D15: =IFERROR(AVERAGEIFS(d_Sal,d_ID,"<>",d_Dept,fDept,d_Sat,">="&fSatLo,d_Sat,"<="&fSatHi,d_Prom,">="&fPromLo,d_Prom,"<="&fPromHi),0) -> 75061.798
B16: Avg job satisfaction | C16: =IFERROR(AVERAGEIFS(d_Sat,d_ID,"<>"),0) -> 2.49625 | D16: =IFERROR(AVERAGEIFS(d_Sat,d_ID,"<>",d_Dept,fDept,d_Sat,">="&fSatLo,d_Sat,"<="&fSatHi,d_Prom,">="&fPromLo,d_Prom,"<="&fPromHi),0) -> 2.49625
B17: Promotion rate | C17: =IFERROR(COUNTIFS(d_ID,"<>",d_Prom,1)/C12,0) -> 0.32625 | D17: =IFERROR(COUNTIFS(d_ID,"<>",d_Prom,1,d_Dept,fDept,d_Sat,">="&fSatLo,d_Sat,"<="&fSatHi,d_Prom,">="&fPromLo,d_Prom,"<="&fPromHi)/D12,0) -> 0.32625
B18: Avg tenure (yrs) | C18: =IFERROR(AVERAGEIFS(d_Ten,d_ID,"<>"),0) -> 9.7675 | D18: =IFERROR(AVERAGEIFS(d_Ten,d_ID,"<>",d_Dept,fDept,d_Sat,">="&fSatLo,d_Sat,"<="&fSatHi,d_Prom,">="&fPromLo,d_Prom,"<="&fPromHi),0) -> 9.7675
B23: Department master (ignores Department filter; respects Satisfaction & Promotion filters)
B24: Department | C24: Headcount | D24: Left | E24: Attrition % | F24: Avg salary | G24: Avg satisfaction | H24: Promotion % | I24: Avg tenure | J24: Headcount (all) | K24: Key: rate | L24: Key: salary | M24: Key: promo
B25: =IF(Settings!B7="","",Settings!B7) -> Finance | C25: =IF($B25="","",COUNTIFS(d_ID,"<>",d_Dept,$B25,d_Sat,">="&fSatLo,d_Sat,"<="&fSatHi,d_Prom,">="&fPromLo,d_Prom,"<="&fPromHi)) -> 170 | D25: =IF($B25="","",COUNTIFS(d_ID,"<>",d_Dept,$B25,d_Sat,">="&fSatLo,d_Sat,"<="&fSatHi,d_Prom,">="&fPromLo,d_Prom,"<="&fPromHi,d_Att,"Yes")) -> 39 | E25: =IF($B25="","",IFERROR(D25/C25,0)) -> 0.22941176 | F25: =IF($B25="","",IFERROR(AVERAGEIFS(d_Sal,d_ID,"<>",d_Dept,$B25,d_Sat,">="&fSatLo,d_Sat,"<="&fSatHi,d_Prom,">="&fPromLo,d_Prom,"<="&fPromHi),0)) -> 74193.429 | G25: =IF($B25="","",IFERROR(AVERAGEIFS(d_Sat,d_ID,"<>",d_Dept,$B25,d_Sat,">="&fSatLo,d_Sat,"<="&fSatHi,d_Prom,">="&fPromLo,d_Prom,"<="&fPromHi),0)) -> 2.5352941 | H25: =IF($B25="","",IFERROR(COUNTIFS(d_ID,"<>",d_Dept,$B25,d_Prom,1,d_Sat,">="&fSatLo,d_Sat,"<="&fSatHi,d_Prom,">="&fPromLo,d_Prom,"<="&fPromHi)/C25,0)) -> 0.34705882 | I25: =IF($B25="","",IFERROR(AVERAGEIFS(d_Ten,d_ID,"<>",d_Dept,$B25,d_Sat,">="&fSatLo,d_Sat,"<="&fSatHi,d_Prom,">="&fPromLo,d_Prom,"<="&fPromHi),0)) -> 8.6941176 | J25: =IF($B25="",0,COUNTIFS(d_ID,"<>",d_Dept,$B25)) -> 170 | K25: =IF($B25="","",E25+ROW()/10^9) -> 0.22941179 | L25: =IF($B25="","",F25+ROW()/10^9) -> 74193.429 | M25: =IF($B25="","",H25+ROW()/10^9) -> 0.34705885
B26: =IF(Settings!B8="","",Settings!B8) -> HR | C26: =IF($B26="","",COUNTIFS(d_ID,"<>",d_Dept,$B26,d_Sat,">="&fSatLo,d_Sat,"<="&fSatHi,d_Prom,">="&fPromLo,d_Prom,"<="&fPromHi)) -> 174 | D26: =IF($B26="","",COUNTIFS(d_ID,"<>",d_Dept,$B26,d_Sat,">="&fSatLo,d_Sat,"<="&fSatHi,d_Prom,">="&fPromLo,d_Prom,"<="&fPromHi,d_Att,"Yes")) -> 31 | E26: =IF($B26="","",IFERROR(D26/C26,0)) -> 0.17816092 | F26: =IF($B26="","",IFERROR(AVERAGEIFS(d_Sal,d_ID,"<>",d_Dept,$B26,d_Sat,">="&fSatLo,d_Sat,"<="&fSatHi,d_Prom,">="&fPromLo,d_Prom,"<="&fPromHi),0)) -> 73784.241 | G26: =IF($B26="","",IFERROR(AVERAGEIFS(d_Sat,d_ID,"<>",d_Dept,$B26,d_Sat,">="&fSatLo,d_Sat,"<="&fSatHi,d_Prom,">="&fPromLo,d_Prom,"<="&fPromHi),0)) -> 2.5517241 | H26: =IF($B26="","",IFERROR(COUNTIFS(d_ID,"<>",d_Dept,$B26,d_Prom,1,d_Sat,">="&fSatLo,d_Sat,"<="&fSatHi,d_Prom,">="&fPromLo,d_Prom,"<="&fPromHi)/C26,0)) -> 0.3045977 | I26: =IF($B26="","",IFERROR(AVERAGEIFS(d_Ten,d_ID,"<>",d_Dept,$B26,d_Sat,">="&fSatLo,d_Sat,"<="&fSatHi,d_Prom,">="&fPromLo,d_Prom,"<="&fPromHi),0)) -> 9.4770115 | J26: =IF($B26="",0,COUNTIFS(d_ID,"<>",d_Dept,$B26)) -> 174 | K26: =IF($B26="","",E26+ROW()/10^9) -> 0.17816095 | L26: =IF($B26="","",F26+ROW()/10^9) -> 73784.241 | M26: =IF($B26="","",H26+ROW()/10^9) -> 0.30459773
B27: =IF(Settings!B9="","",Settings!B9) -> IT | C27: =IF($B27="","",COUNTIFS(d_ID,"<>",d_Dept,$B27,d_Sat,">="&fSatLo,d_Sat,"<="&fSatHi,d_Prom,">="&fPromLo,d_Prom,"<="&fPromHi)) -> 159 | D27: =IF($B27="","",COUNTIFS(d_ID,"<>",d_Dept,$B27,d_Sat,">="&fSatLo,d_Sat,"<="&fSatHi,d_Prom,">="&fPromLo,d_Prom,"<="&fPromHi,d_Att,"Yes")) -> 21 | E27: =IF($B27="","",IFERROR(D27/C27,0)) -> 0.13207547 | F27: =IF($B27="","",IFERROR(AVERAGEIFS(d_Sal,d_ID,"<>",d_Dept,$B27,d_Sat,">="&fSatLo,d_Sat,"<="&fSatHi,d_Prom,">="&fPromLo,d_Prom,"<="&fPromHi),0)) -> 77438.679 | G27: =IF($B27="","",IFERROR(AVERAGEIFS(d_Sat,d_ID,"<>",d_Dept,$B27,d_Sat,">="&fSatLo,d_Sat,"<="&fSatHi,d_Prom,">="&fPromLo,d_Prom,"<="&fPromHi),0)) -> 2.4779874 | H27: =IF($B27="","",IFERROR(COUNTIFS(d_ID,"<>",d_Dept,$B27,d_Prom,1,d_Sat,">="&fSatLo,d_Sat,"<="&fSatHi,d_Prom,">="&fPromLo,d_Prom,"<="&fPromHi)/C27,0)) -> 0.36477987 | I27: =IF($B27="","",IFERROR(AVERAGEIFS(d_Ten,d_ID,"<>",d_Dept,$B27,d_Sat,">="&fSatLo,d_Sat,"<="&fSatHi,d_Prom,">="&fPromLo,d_Prom,"<="&fPromHi),0)) -> 10.188679 | J27: =IF($B27="",0,COUNTIFS(d_ID,"<>",d_Dept,$B27)) -> 159 | K27: =IF($B27="","",E27+ROW()/10^9) -> 0.1320755 | L27: =IF($B27="","",F27+ROW()/10^9) -> 77438.679 | M27: =IF($B27="","",H27+ROW()/10^9) -> 0.3647799
B28: =IF(Settings!B10="","",Settings!B10) -> Operations | C28: =IF($B28="","",COUNTIFS(d_ID,"<>",d_Dept,$B28,d_Sat,">="&fSatLo,d_Sat,"<="&fSatHi,d_Prom,">="&fPromLo,d_Prom,"<="&fPromHi)) -> 142 | D28: =IF($B28="","",COUNTIFS(d_ID,"<>",d_Dept,$B28,d_Sat,">="&fSatLo,d_Sat,"<="&fSatHi,d_Prom,">="&fPromLo,d_Prom,"<="&fPromHi,d_Att,"Yes")) -> 23 | E28: =IF($B28="","",IFERROR(D28/C28,0)) -> 0.16197183 | F28: =IF($B28="","",IFERROR(AVERAGEIFS(d_Sal,d_ID,"<>",d_Dept,$B28,d_Sat,">="&fSatLo,d_Sat,"<="&fSatHi,d_Prom,">="&fPromLo,d_Prom,"<="&fPromHi),0)) -> 75429.458 | G28: =IF($B28="","",IFERROR(AVERAGEIFS(d_Sat,d_ID,"<>",d_Dept,$B28,d_Sat,">="&fSatLo,d_Sat,"<="&fSatHi,d_Prom,">="&fPromLo,d_Prom,"<="&fPromHi),0)) -> 2.3943662 | H28: =IF($B28="","",IFERROR(COUNTIFS(d_ID,"<>",d_Dept,$B28,d_Prom,1,d_Sat,">="&fSatLo,d_Sat,"<="&fSatHi,d_Prom,">="&fPromLo,d_Prom,"<="&fPromHi)/C28,0)) -> 0.30985915 | I28: =IF($B28="","",IFERROR(AVERAGEIFS(d_Ten,d_ID,"<>",d_Dept,$B28,d_Sat,">="&fSatLo,d_Sat,"<="&fSatHi,d_Prom,">="&fPromLo,d_Prom,"<="&fPromHi),0)) -> 10.112676 | J28: =IF($B28="",0,COUNTIFS(d_ID,"<>",d_Dept,$B28)) -> 142 | K28: =IF($B28="","",E28+ROW()/10^9) -> 0.16197186 | L28: =IF($B28="","",F28+ROW()/10^9) -> 75429.458 | M28: =IF($B28="","",H28+ROW()/10^9) -> 0.30985918
B29: =IF(Settings!B11="","",Settings!B11) -> Sales | C29: =IF($B29="","",COUNTIFS(d_ID,"<>",d_Dept,$B29,d_Sat,">="&fSatLo,d_Sat,"<="&fSatHi,d_Prom,">="&fPromLo,d_Prom,"<="&fPromHi)) -> 155 | D29: =IF($B29="","",COUNTIFS(d_ID,"<>",d_Dept,$B29,d_Sat,">="&fSatLo,d_Sat,"<="&fSatHi,d_Prom,">="&fPromLo,d_Prom,"<="&fPromHi,d_Att,"Yes")) -> 32 | E29: =IF($B29="","",IFERROR(D29/C29,0)) -> 0.20645161 | F29: =IF($B29="","",IFERROR(AVERAGEIFS(d_Sal,d_ID,"<>",d_Dept,$B29,d_Sat,">="&fSatLo,d_Sat,"<="&fSatHi,d_Prom,">="&fPromLo,d_Prom,"<="&fPromHi),0)) -> 74673.316 | G29: =IF($B29="","",IFERROR(AVERAGEIFS(d_Sat,d_ID,"<>",d_Dept,$B29,d_Sat,">="&fSatLo,d_Sat,"<="&fSatHi,d_Prom,">="&fPromLo,d_Prom,"<="&fPromHi),0)) -> 2.5032258 | H29: =IF($B29="","",IFERROR(COUNTIFS(d_ID,"<>",d_Dept,$B29,d_Prom,1,d_Sat,">="&fSatLo,d_Sat,"<="&fSatHi,d_Prom,">="&fPromLo,d_Prom,"<="&fPromHi)/C29,0)) -> 0.30322581 | I29: =IF($B29="","",IFERROR(AVERAGEIFS(d_Ten,d_ID,"<>",d_Dept,$B29,d_Sat,">="&fSatLo,d_Sat,"<="&fSatHi,d_Prom,">="&fPromLo,d_Prom,"<="&fPromHi),0)) -> 10.522581 | J29: =IF($B29="",0,COUNTIFS(d_ID,"<>",d_Dept,$B29)) -> 155 | K29: =IF($B29="","",E29+ROW()/10^9) -> 0.20645164 | L29: =IF($B29="","",F29+ROW()/10^9) -> 74673.316 | M29: =IF($B29="","",H29+ROW()/10^9) -> 0.30322584
B30: =IF(Settings!B12="","",Settings!B12) | C30: =IF($B30="","",COUNTIFS(d_ID,"<>",d_Dept,$B30,d_Sat,">="&fSatLo,d_Sat,"<="&fSatHi,d_Prom,">="&fPromLo,d_Prom,"<="&fPromHi)) | D30: =IF($B30="","",COUNTIFS(d_ID,"<>",d_Dept,$B30,d_Sat,">="&fSatLo,d_Sat,"<="&fSatHi,d_Prom,">="&fPromLo,d_Prom,"<="&fPromHi,d_Att,"Yes")) | E30: =IF($B30="","",IFERROR(D30/C30,0)) | F30: =IF($B30="","",IFERROR(AVERAGEIFS(d_Sal,d_ID,"<>",d_Dept,$B30,d_Sat,">="&fSatLo,d_Sat,"<="&fSatHi,d_Prom,">="&fPromLo,d_Prom,"<="&fPromHi),0)) | G30: =IF($B30="","",IFERROR(AVERAGEIFS(d_Sat,d_ID,"<>",d_Dept,$B30,d_Sat,">="&fSatLo,d_Sat,"<="&fSatHi,d_Prom,">="&fPromLo,d_Prom,"<="&fPromHi),0)) | H30: =IF($B30="","",IFERROR(COUNTIFS(d_ID,"<>",d_Dept,$B30,d_Prom,1,d_Sat,">="&fSatLo,d_Sat,"<="&fSatHi,d_Prom,">="&fPromLo,d_Prom,"<="&fPromHi)/C30,0)) | I30: =IF($B30="","",IFERROR(AVERAGEIFS(d_Ten,d_ID,"<>",d_Dept,$B30,d_Sat,">="&fSatLo,d_Sat,"<="&fSatHi,d_Prom,">="&fPromLo,d_Prom,"<="&fPromHi),0)) | J30: =IF($B30="",0,COUNTIFS(d_ID,"<>",d_Dept,$B30)) -> 0 | K30: =IF($B30="","",E30+ROW()/10^9) | L30: =IF($B30="","",F30+ROW()/10^9) | M30: =IF($B30="","",H30+ROW()/10^9)
B31: =IF(Settings!B13="","",Settings!B13) | C31: =IF($B31="","",COUNTIFS(d_ID,"<>",d_Dept,$B31,d_Sat,">="&fSatLo,d_Sat,"<="&fSatHi,d_Prom,">="&fPromLo,d_Prom,"<="&fPromHi)) | D31: =IF($B31="","",COUNTIFS(d_ID,"<>",d_Dept,$B31,d_Sat,">="&fSatLo,d_Sat,"<="&fSatHi,d_Prom,">="&fPromLo,d_Prom,"<="&fPromHi,d_Att,"Yes")) | E31: =IF($B31="","",IFERROR(D31/C31,0)) | F31: =IF($B31="","",IFERROR(AVERAGEIFS(d_Sal,d_ID,"<>",d_Dept,$B31,d_Sat,">="&fSatLo,d_Sat,"<="&fSatHi,d_Prom,">="&fPromLo,d_Prom,"<="&fPromHi),0)) | G31: =IF($B31="","",IFERROR(AVERAGEIFS(d_Sat,d_ID,"<>",d_Dept,$B31,d_Sat,">="&fSatLo,d_Sat,"<="&fSatHi,d_Prom,">="&fPromLo,d_Prom,"<="&fPromHi),0)) | H31: =IF($B31="","",IFERROR(COUNTIFS(d_ID,"<>",d_Dept,$B31,d_Prom,1,d_Sat,">="&fSatLo,d_Sat,"<="&fSatHi,d_Prom,">="&fPromLo,d_Prom,"<="&fPromHi)/C31,0)) | I31: =IF($B31="","",IFERROR(AVERAGEIFS(d_Ten,d_ID,"<>",d_Dept,$B31,d_Sat,">="&fSatLo,d_Sat,"<="&fSatHi,d_Prom,">="&fPromLo,d_Prom,"<="&fPromHi),0)) | J31: =IF($B31="",0,COUNTIFS(d_ID,"<>",d_Dept,$B31)) -> 0 | K31: =IF($B31="","",E31+ROW()/10^9) | L31: =IF($B31="","",F31+ROW()/10^9) | M31: =IF($B31="","",H31+ROW()/10^9)
B32: =IF(Settings!B14="","",Settings!B14) | C32: =IF($B32="","",COUNTIFS(d_ID,"<>",d_Dept,$B32,d_Sat,">="&fSatLo,d_Sat,"<="&fSatHi,d_Prom,">="&fPromLo,d_Prom,"<="&fPromHi)) | D32: =IF($B32="","",COUNTIFS(d_ID,"<>",d_Dept,$B32,d_Sat,">="&fSatLo,d_Sat,"<="&fSatHi,d_Prom,">="&fPromLo,d_Prom,"<="&fPromHi,d_Att,"Yes")) | E32: =IF($B32="","",IFERROR(D32/C32,0)) | F32: =IF($B32="","",IFERROR(AVERAGEIFS(d_Sal,d_ID,"<>",d_Dept,$B32,d_Sat,">="&fSatLo,d_Sat,"<="&fSatHi,d_Prom,">="&fPromLo,d_Prom,"<="&fPromHi),0)) | G32: =IF($B32="","",IFERROR(AVERAGEIFS(d_Sat,d_ID,"<>",d_Dept,$B32,d_Sat,">="&fSatLo,d_Sat,"<="&fSatHi,d_Prom,">="&fPromLo,d_Prom,"<="&fPromHi),0)) | H32: =IF($B32="","",IFERROR(COUNTIFS(d_ID,"<>",d_Dept,$B32,d_Prom,1,d_Sat,">="&fSatLo,d_Sat,"<="&fSatHi,d_Prom,">="&fPromLo,d_Prom,"<="&fPromHi)/C32,0)) | I32: =IF($B32="","",IFERROR(AVERAGEIFS(d_Ten,d_ID,"<>",d_Dept,$B32,d_Sat,">="&fSatLo,d_Sat,"<="&fSatHi,d_Prom,">="&fPromLo,d_Prom,"<="&fPromHi),0)) | J32: =IF($B32="",0,COUNTIFS(d_ID,"<>",d_Dept,$B32)) -> 0 | K32: =IF($B32="","",E32+ROW()/10^9) | L32: =IF($B32="","",F32+ROW()/10^9) | M32: =IF($B32="","",H32+ROW()/10^9)
B33: All departments | C33: =COUNTIFS(d_ID,"<>",d_Sat,">="&fSatLo,d_Sat,"<="&fSatHi,d_Prom,">="&fPromLo,d_Prom,"<="&fPromHi) -> 800 | D33: =COUNTIFS(d_ID,"<>",d_Sat,">="&fSatLo,d_Sat,"<="&fSatHi,d_Prom,">="&fPromLo,d_Prom,"<="&fPromHi,d_Att,"Yes") -> 146 | E33: =IFERROR(D33/C33,0) -> 0.1825 | F33: =IFERROR(AVERAGEIFS(d_Sal,d_ID,"<>",d_Sat,">="&fSatLo,d_Sat,"<="&fSatHi,d_Prom,">="&fPromLo,d_Prom,"<="&fPromHi),0) -> 75061.798 | G33: =IFERROR(AVERAGEIFS(d_Sat,d_ID,"<>",d_Sat,">="&fSatLo,d_Sat,"<="&fSatHi,d_Prom,">="&fPromLo,d_Prom,"<="&fPromHi),0) -> 2.49625 | H33: =IFERROR(COUNTIFS(d_ID,"<>",d_Prom,1,d_Sat,">="&fSatLo,d_Sat,"<="&fSatHi,d_Prom,">="&fPromLo,d_Prom,"<="&fPromHi)/C33,0) -> 0.32625 | I33: =IFERROR(AVERAGEIFS(d_Ten,d_ID,"<>",d_Sat,">="&fSatLo,d_Sat,"<="&fSatHi,d_Prom,">="&fPromLo,d_Prom,"<="&fPromHi),0) -> 9.7675
B34: Departments in scope | C34: =COUNTIF(B25:B32,"?*") -> 5
B36: Sorted views (feed the ranked bar charts)
B37: Rank | C37: Pos | D37: Dept (by attrition) | E37: Attrition % | G37: Pos | H37: Dept (by salary) | I37: Avg salary | K37: Pos | L37: Dept (by promo) | M37: Promotion %
B38: 1 | C38: =IF($B38>$C$34,"",MATCH(LARGE($K$25:$K$32,$B38),$K$25:$K$32,0)) -> 1 | D38: =IF(C38="","",INDEX($B$25:$B$32,C38)) -> Finance | E38: =IF(C38="","",INDEX($E$25:$E$32,C38)) -> 0.22941176 | G38: =IF($B38>$C$34,"",MATCH(LARGE($L$25:$L$32,$B38),$L$25:$L$32,0)) -> 3 | H38: =IF(G38="","",INDEX($B$25:$B$32,G38)) -> IT | I38: =IF(G38="","",INDEX($F$25:$F$32,G38)) -> 77438.679 | K38: =IF($B38>$C$34,"",MATCH(LARGE($M$25:$M$32,$B38),$M$25:$M$32,0)) -> 3 | L38: =IF(K38="","",INDEX($B$25:$B$32,K38)) -> IT | M38: =IF(K38="","",INDEX($H$25:$H$32,K38)) -> 0.36477987
B39: 2 | C39: =IF($B39>$C$34,"",MATCH(LARGE($K$25:$K$32,$B39),$K$25:$K$32,0)) -> 5 | D39: =IF(C39="","",INDEX($B$25:$B$32,C39)) -> Sales | E39: =IF(C39="","",INDEX($E$25:$E$32,C39)) -> 0.20645161 | G39: =IF($B39>$C$34,"",MATCH(LARGE($L$25:$L$32,$B39),$L$25:$L$32,0)) -> 4 | H39: =IF(G39="","",INDEX($B$25:$B$32,G39)) -> Operations | I39: =IF(G39="","",INDEX($F$25:$F$32,G39)) -> 75429.458 | K39: =IF($B39>$C$34,"",MATCH(LARGE($M$25:$M$32,$B39),$M$25:$M$32,0)) -> 1 | L39: =IF(K39="","",INDEX($B$25:$B$32,K39)) -> Finance | M39: =IF(K39="","",INDEX($H$25:$H$32,K39)) -> 0.34705882
B40: 3 | C40: =IF($B40>$C$34,"",MATCH(LARGE($K$25:$K$32,$B40),$K$25:$K$32,0)) -> 2 | D40: =IF(C40="","",INDEX($B$25:$B$32,C40)) -> HR | E40: =IF(C40="","",INDEX($E$25:$E$32,C40)) -> 0.17816092 | G40: =IF($B40>$C$34,"",MATCH(LARGE($L$25:$L$32,$B40),$L$25:$L$32,0)) -> 5 | H40: =IF(G40="","",INDEX($B$25:$B$32,G40)) -> Sales | I40: =IF(G40="","",INDEX($F$25:$F$32,G40)) -> 74673.316 | K40: =IF($B40>$C$34,"",MATCH(LARGE($M$25:$M$32,$B40),$M$25:$M$32,0)) -> 4 | L40: =IF(K40="","",INDEX($B$25:$B$32,K40)) -> Operations | M40: =IF(K40="","",INDEX($H$25:$H$32,K40)) -> 0.30985915
B41: 4 | C41: =IF($B41>$C$34,"",MATCH(LARGE($K$25:$K$32,$B41),$K$25:$K$32,0)) -> 4 | D41: =IF(C41="","",INDEX($B$25:$B$32,C41)) -> Operations | E41: =IF(C41="","",INDEX($E$25:$E$32,C41)) -> 0.16197183 | G41: =IF($B41>$C$34,"",MATCH(LARGE($L$25:$L$32,$B41),$L$25:$L$32,0)) -> 1 | H41: =IF(G41="","",INDEX($B$25:$B$32,G41)) -> Finance | I41: =IF(G41="","",INDEX($F$25:$F$32,G41)) -> 74193.429 | K41: =IF($B41>$C$34,"",MATCH(LARGE($M$25:$M$32,$B41),$M$25:$M$32,0)) -> 2 | L41: =IF(K41="","",INDEX($B$25:$B$32,K41)) -> HR | M41: =IF(K41="","",INDEX($H$25:$H$32,K41)) -> 0.3045977
B42: 5 | C42: =IF($B42>$C$34,"",MATCH(LARGE($K$25:$K$32,$B42),$K$25:$K$32,0)) -> 3 | D42: =IF(C42="","",INDEX($B$25:$B$32,C42)) -> IT | E42: =IF(C42="","",INDEX($E$25:$E$32,C42)) -> 0.13207547 | G42: =IF($B42>$C$34,"",MATCH(LARGE($L$25:$L$32,$B42),$L$25:$L$32,0)) -> 2 | H42: =IF(G42="","",INDEX($B$25:$B$32,G42)) -> HR | I42: =IF(G42="","",INDEX($F$25:$F$32,G42)) -> 73784.241 | K42: =IF($B42>$C$34,"",MATCH(LARGE($M$25:$M$32,$B42),$M$25:$M$32,0)) -> 5 | L42: =IF(K42="","",INDEX($B$25:$B$32,K42)) -> Sales | M42: =IF(K42="","",INDEX($H$25:$H$32,K42)) -> 0.30322581
B43: 6 | C43: =IF($B43>$C$34,"",MATCH(LARGE($K$25:$K$32,$B43),$K$25:$K$32,0)) | D43: =IF(C43="","",INDEX($B$25:$B$32,C43)) | E43: =IF(C43="","",INDEX($E$25:$E$32,C43)) | G43: =IF($B43>$C$34,"",MATCH(LARGE($L$25:$L$32,$B43),$L$25:$L$32,0)) | H43: =IF(G43="","",INDEX($B$25:$B$32,G43)) | I43: =IF(G43="","",INDEX($F$25:$F$32,G43)) | K43: =IF($B43>$C$34,"",MATCH(LARGE($M$25:$M$32,$B43),$M$25:$M$32,0)) | L43: =IF(K43="","",INDEX($B$25:$B$32,K43)) | M43: =IF(K43="","",INDEX($H$25:$H$32,K43))
B44: 7 | C44: =IF($B44>$C$34,"",MATCH(LARGE($K$25:$K$32,$B44),$K$25:$K$32,0)) | D44: =IF(C44="","",INDEX($B$25:$B$32,C44)) | E44: =IF(C44="","",INDEX($E$25:$E$32,C44)) | G44: =IF($B44>$C$34,"",MATCH(LARGE($L$25:$L$32,$B44),$L$25:$L$32,0)) | H44: =IF(G44="","",INDEX($B$25:$B$32,G44)) | I44: =IF(G44="","",INDEX($F$25:$F$32,G44)) | K44: =IF($B44>$C$34,"",MATCH(LARGE($M$25:$M$32,$B44),$M$25:$M$32,0)) | L44: =IF(K44="","",INDEX($B$25:$B$32,K44)) | M44: =IF(K44="","",INDEX($H$25:$H$32,K44))
B45: 8 | C45: =IF($B45>$C$34,"",MATCH(LARGE($K$25:$K$32,$B45),$K$25:$K$32,0)) | D45: =IF(C45="","",INDEX($B$25:$B$32,C45)) | E45: =IF(C45="","",INDEX($E$25:$E$32,C45)) | G45: =IF($B45>$C$34,"",MATCH(LARGE($L$25:$L$32,$B45),$L$25:$L$32,0)) | H45: =IF(G45="","",INDEX($B$25:$B$32,G45)) | I45: =IF(G45="","",INDEX($F$25:$F$32,G45)) | K45: =IF($B45>$C$34,"",MATCH(LARGE($M$25:$M$32,$B45),$M$25:$M$32,0)) | L45: =IF(K45="","",INDEX($B$25:$B$32,K45)) | M45: =IF(K45="","",INDEX($H$25:$H$32,K45))
B48: By job satisfaction (ignores Satisfaction filter)
B49: Level | C49: Headcount | D49: Left | E49: Attrition % | F49: Avg salary | G49: Promotion % | H49: Label
...

Sheet Guide
B2: How this workbook works
B4: Dashboard | C4: Executive view: filters, KPI cards, auto-written insights, 14 charts, heatmap and department scorecard. Nothing to edit here except the three blue dropdowns.
B5: Data | C5: Your 800-employee dataset as an Excel Table (tblHR). Edit values, or paste / type new rows directly under the last row — the dashboard reads rows 2–5,000. Drop-downs and red duplicate-ID highlighting protect data quality.
B6: Settings | C6: Department list, satisfaction scale, tenure / age / salary band limits and the attrition target (an assumption — set your own). Also holds the automatic data-quality checks.
B7: Calc | C7: The formula engine (COUNTIFS / AVERAGEIFS over the Data sheet). All charts and KPIs read from here. Not for editing.
B8: Keeping it live | C8: 1) Change or add rows on Data 2) Dashboard recalculates automatically 3) If you add a new department, type it in the next empty cell of the Settings department list. KPIs, heatmap and scorecard pick it up at once (up to 8 departments); extend the three department charts’ data range by one row to show it in the bar charts.
B9: Filters | C9: Department, Job satisfaction and Promotion. Every chart ignores the filter for its own dimension so comparisons stay visible. Select “All” to reset.
B10: Colour code | C10: Blue text = editable input · Black = formula · Yellow fill = assumption to confirm.
B11: Changes vs. original | C11: The original pivot tables and pivot charts were replaced by formula-driven equivalents so they never need a manual Refresh. The helper columns I–L (Total Employees, Employees Left, Attrition Rate, Column1) on the data sheet were removed — those values are now computed automatically.
